<?xml version="1.0" ?>
<robot name="(Unsaved)" xmlns:xacro="http://www.ros.org/wiki/xacro">

<xacro:include filename="$(find (Unsaved)_description)/urdf/materials.xacro" />
<xacro:include filename="$(find (Unsaved)_description)/urdf/(Unsaved).trans" />
<xacro:include filename="$(find (Unsaved)_description)/urdf/(Unsaved).gazebo" />
<link name="base_link">
  <inertial>
    <origin xyz="0.0 5.368319708083674e-18 0.010706402393346059" rpy="0 0 0"/>
    <mass value="0.8312113702643654"/>
    <inertia ixx="0.0002" iyy="0.000688" izz="0.000822" ixy="0.0" iyz="0.0" ixz="0.0"/>
  </inertial>
  <visual>
    <origin xyz="0 0 0" rpy="0 0 0"/>
    <geometry>
      <mesh filename="package://(Unsaved)_description/meshes/base_link.stl" scale="0.001 0.001 0.001"/>
    </geometry>
    <material name="silver"/>
  </visual>
  <collision>
    <origin xyz="0 0 0" rpy="0 0 0"/>
    <geometry>
      <mesh filename="package://(Unsaved)_description/meshes/base_link.stl" scale="0.001 0.001 0.001"/>
    </geometry>
  </collision>
</link>

<link name="old_component__3__1">
  <inertial>
    <origin xyz="-1.3877787807814457e-17 0.0049999999999999975 -7.237528875152536e-18" rpy="0 0 0"/>
    <mass value="0.1541343895667492"/>
    <inertia ixx="2.5e-05" iyy="4.8e-05" izz="2.5e-05" ixy="-0.0" iyz="-0.0" ixz="-0.0"/>
  </inertial>
  <visual>
    <origin xyz="-0.05 -0.025 -0.0" rpy="0 0 0"/>
    <geometry>
      <mesh filename="package://(Unsaved)_description/meshes/old_component__3__1.stl" scale="0.001 0.001 0.001"/>
    </geometry>
    <material name="silver"/>
  </visual>
  <collision>
    <origin xyz="-0.05 -0.025 -0.0" rpy="0 0 0"/>
    <geometry>
      <mesh filename="package://(Unsaved)_description/meshes/old_component__3__1.stl" scale="0.001 0.001 0.001"/>
    </geometry>
  </collision>
</link>

<link name="old_component__2__1">
  <inertial>
    <origin xyz="0.0 -0.0049999999999999975 -7.237528875152536e-18" rpy="0 0 0"/>
    <mass value="0.1541343895667492"/>
    <inertia ixx="2.5e-05" iyy="4.8e-05" izz="2.5e-05" ixy="-0.0" iyz="-0.0" ixz="0.0"/>
  </inertial>
  <visual>
    <origin xyz="0.05 0.025 -0.0" rpy="0 0 0"/>
    <geometry>
      <mesh filename="package://(Unsaved)_description/meshes/old_component__2__1.stl" scale="0.001 0.001 0.001"/>
    </geometry>
    <material name="silver"/>
  </visual>
  <collision>
    <origin xyz="0.05 0.025 -0.0" rpy="0 0 0"/>
    <geometry>
      <mesh filename="package://(Unsaved)_description/meshes/old_component__2__1.stl" scale="0.001 0.001 0.001"/>
    </geometry>
  </collision>
</link>

<link name="old_component__1__1">
  <inertial>
    <origin xyz="-1.3877787807814457e-17 -0.0049999999999999975 -7.237528875152536e-18" rpy="0 0 0"/>
    <mass value="0.1541343895667492"/>
    <inertia ixx="2.5e-05" iyy="4.8e-05" izz="2.5e-05" ixy="0.0" iyz="-0.0" ixz="-0.0"/>
  </inertial>
  <visual>
    <origin xyz="-0.05 0.025 -0.0" rpy="0 0 0"/>
    <geometry>
      <mesh filename="package://(Unsaved)_description/meshes/old_component__1__1.stl" scale="0.001 0.001 0.001"/>
    </geometry>
    <material name="silver"/>
  </visual>
  <collision>
    <origin xyz="-0.05 0.025 -0.0" rpy="0 0 0"/>
    <geometry>
      <mesh filename="package://(Unsaved)_description/meshes/old_component__1__1.stl" scale="0.001 0.001 0.001"/>
    </geometry>
  </collision>
</link>

<link name="old_component__4__1">
  <inertial>
    <origin xyz="0.0 0.0049999999999999975 -7.237528875152536e-18" rpy="0 0 0"/>
    <mass value="0.1541343895667492"/>
    <inertia ixx="2.5e-05" iyy="4.8e-05" izz="2.5e-05" ixy="0.0" iyz="-0.0" ixz="0.0"/>
  </inertial>
  <visual>
    <origin xyz="0.05 -0.025 -0.0" rpy="0 0 0"/>
    <geometry>
      <mesh filename="package://(Unsaved)_description/meshes/old_component__4__1.stl" scale="0.001 0.001 0.001"/>
    </geometry>
    <material name="silver"/>
  </visual>
  <collision>
    <origin xyz="0.05 -0.025 -0.0" rpy="0 0 0"/>
    <geometry>
      <mesh filename="package://(Unsaved)_description/meshes/old_component__4__1.stl" scale="0.001 0.001 0.001"/>
    </geometry>
  </collision>
</link>

<link name="old_component__5__1">
  <inertial>
    <origin xyz="0.0033314114426794615 0.0 0.015066728253167239" rpy="0 0 0"/>
    <mass value="0.2590533019895481"/>
    <inertia ixx="5.3e-05" iyy="0.000131" izz="0.000118" ixy="0.0" iyz="0.0" ixz="4e-06"/>
  </inertial>
  <visual>
    <origin xyz="-0.0 -0.0 -0.025" rpy="0 0 0"/>
    <geometry>
      <mesh filename="package://(Unsaved)_description/meshes/old_component__5__1.stl" scale="0.001 0.001 0.001"/>
    </geometry>
    <material name="silver"/>
  </visual>
  <collision>
    <origin xyz="-0.0 -0.0 -0.025" rpy="0 0 0"/>
    <geometry>
      <mesh filename="package://(Unsaved)_description/meshes/old_component__5__1.stl" scale="0.001 0.001 0.001"/>
    </geometry>
  </collision>
</link>

<joint name="Revolute 1" type="continuous">
  <origin xyz="0.05 0.025 0.0" rpy="0 0 0"/>
  <parent link="base_link"/>
  <child link="old_component__3__1"/>
  <axis xyz="0.0 1.0 0.0"/>
</joint>

<joint name="Revolute 2" type="continuous">
  <origin xyz="-0.05 -0.025 0.0" rpy="0 0 0"/>
  <parent link="base_link"/>
  <child link="old_component__2__1"/>
  <axis xyz="0.0 -1.0 0.0"/>
</joint>

<joint name="Revolute 3" type="continuous">
  <origin xyz="0.05 -0.025 0.0" rpy="0 0 0"/>
  <parent link="base_link"/>
  <child link="old_component__1__1"/>
  <axis xyz="0.0 -1.0 0.0"/>
</joint>

<joint name="Revolute 4" type="continuous">
  <origin xyz="-0.05 0.025 0.0" rpy="0 0 0"/>
  <parent link="base_link"/>
  <child link="old_component__4__1"/>
  <axis xyz="0.0 1.0 0.0"/>
</joint>

<joint name="Revolute 5" type="continuous">
  <origin xyz="0.0 0.0 0.025" rpy="0 0 0"/>
  <parent link="base_link"/>
  <child link="old_component__5__1"/>
  <axis xyz="0.0 0.0 1.0"/>
</joint>

</robot>
